Exception thrown
g.~Foo() called during stack unwinding
Exception caught: test exception
f.~Foo() called normally